Workbook

Sheet PAGE 1
A2: P-7 | I2: TAUNANG ULAT UKOL SA IMBENTARYO | BS2: YEAR
I3: (ANNUAL INVENTORY REPORT) | BS3: 2 0 2 4
A5: Lokal: | F5: Balayan | AA5: Distrito: | AF5: Batangas | BA5: Petsa ng Pag-uulat: | BK5: 45733
BA6: Dcode: | BE6: 1009 | BN6: Lcode: | BR6: 003
A7: 1. UKOL SA MGA GUSALI:
A8: A. KAPILYA
A9: Class | G9: Concrete (A-3) | R9: ( | S9: ⁄ | T9: ) | V9: Handog | AF9: Petsa ng Ihandog: | AO9: Abril 29, 1989 | BD9: Original na Halaga ng Kapilya
A10: S. Cap. | G10: 300 | R10: ( | T10: ) | V10: Di-Handog | AF10: Petsa ng Mayari: | AO10: Abril 1989 | BD10: ₱ | BG10: 1897535.5
A11: PAGAWA NG: | M11: ( | N11: ⁄ | O11: ) | Q11: Central | X11: ( | Z11: ) | AB11: Distrito | AJ11: ( | AL11: ) | AN11: Lokal | AU11: ( | AW11: ) | AY11: Iba pa , specify:
A12: 1. | D12: Kabuuang Halaga ng Kapilya ayon sa ulat ng nakaraang taon | BD12: ₱ | BG12: =+BG10 -> 1897535.5
A13: 2. | D13: NADAGDAG sa taong ito::
F14: Construction | X14: ₱
F15: Renovation
F16: General Repair
F17: Iba Pa
F18: KABUUAN NG NADAGDAG | AP18: ₱ | AR18: Wala po
A19: 3 | D19: NABAWAS sa taong ito (Anong bahagi ang nasira o nabawas? | AP19: ₱ | AR19: Wala po
A21: KABUUANG HALAGA NG KAPILYA SA TAONG ITO | BD21: ₱ | BG21: =+BG12 -> 1897535.5 | CA21: =+BG21 -> 1897535.5
A22: PANSIN:
A24: B. PASTORAL & RES. HOUSES:
D25: RESIDENSIYA / PASTORAL | W25: CLASS | AC25: PETSA | AI25: DATING | AT25: NADAGDAG SA | BE25: NABAWAS SA | BP25: KABUUAN
D26: HOUSE AT IBA PA | AC26: MAYARI | AI26: HALAGA | AT26: TAONG ITO | BE26: TAONG ITO
D27: Pastoral House at | W27: (A-PH)
D28: Bahay ng Bantay Kapilya | AC28: 32627 | AI28: ₱ | AK28: 288611.12 | AT28: Wala po | BE28: Wala po | BP28: =+AI28 -> ₱ | BR28: =+AK28 -> 288611.12
A32: KABUUANG HALAGA NG PASTORAL HOUSE AT IBA PANG RESIDENSIYA | BE32: =+BP28 -> ₱ | BR32: =+BR28 -> 288611.12 | CA32: =+BR32 -> 288611.12
A33: C. OPISINA:
D34: MGA OPISINA NG LOKAL | W34: CLASS | AC34: PETSA | AI34: DATING | AT34: NADAGDAG SA | BE34: NABAWAS SA | BP34: KABUUAN
D35: (BUKOD NA GUSALI) | AC35: MAYARI | AI35: HALAGA | AT35: TAONG ITO | BE35: TAONG ITO
D36: Opisina (Ministerial, | W36: CON.
D37: Pananalapi, Kalihiman) | W37: (ADL-1) | AC37: 32627 | AI37: ₱ | AK37: 125874.82 | AT37: Wala po | BE37: Wala po | BP37: =+AI37 -> ₱ | BR37: =+AK37 -> 125874.82
A39: KABUUANG HALAGA NG MGA OPISINA SA TAONG ITO | BE39: =+BE32 -> ₱ | BR39: =+BR37 -> 125874.82 | CA39: =+BR39 -> 125874.82
A40: D. IBA PANG MGA GUSALI:
D41: IBA PANG MGA GUSALI | W41: CLASS | AC41: PETSA | AI41: DATING | AT41: NADAGDAG SA | BE41: NABAWAS SA | BP41: KABUUAN
AI42: HALAGA | AT42: TAONG ITO | BE42: TAONG ITO
D43: Pump House | W43: (APH-1) | AC43: 32627 | AI43: ₱ | AK43: 114267.69 | AT43: Wala po | BE43: Wala po | BP43: =+AI43 -> ₱ | BR43: =+AK43 -> 114267.69
D44: Guard House | AC44: 32627 | AI44: ₱ | AK44: 12004.8 | AT44: Wala po | BE44: Wala po | BP44: =+AI44 -> ₱ | BR44: =+AK44 -> 12004.8
A46: KABUUANG HALAGA NG IBA PANG MGA GUSALI SA TAONG ITO | BE46: =+BE39 -> ₱ | BR46: =+BR43+BR44+BR45 -> 126272.49 | CA46: =+BR46 -> 126272.49
A48: KABUUANG HALAGA NG MGA GUSALI SA TAONG ITO | BE48: ₱ | BH48: =+BG21+BR32+BR39+BR46 -> 2438293.9 | CA48: =+BH48 -> 2438293.9
BH49: Page 1

Sheet PAGE 2
A2: Taunang ulat ukol sa Imbentaryo (P-7)
A3: Lokal: | G3: Balayan | AF3: Distrito: | AM3: Batangas | BU3: Dcode: | CA3: 1009 | CJ3: Lcode: | CP3: 003 | DG3: Year: | DM3: 2024
A5: II-A. Mga kagamitan ng lokal ayon sa ulat ng nakaraang taon: (Tiyakin na ang lahat ng dati ng kagamitan na nasa ulat ng nakaraang taon ay nakatala sa bahaging ito ng ayon sa bawat dakong kinaroroonan ng mga ito. Huwag itala
A6: sa bahaging ito ang mga kagamitang hindi naisama sa ulat ng nakaraang taon at ang mga nadagdag sa taong ito.)
V8: Date | AW8: D E S C R I P T I O N
A9: Kaukulan | N9: IIN | V9: Received | AB9: Qty | AG9: Items | AW9: Brand | BE9: Model | BM9: Make | BU9: Color | CC9: Size | CK9: Serial# | CS9: Unit Price | DA9: Amount | DJ9: Remarks
A10: Kapilya | N10: 01-0001-02 | V10: 1988 | AB10: 2 | AG10: Benches | BM10: Wooden | BU10: Brown | CC10: .90x4.00m. | CS10: ₱ | CU10: 1605.3 | DA10: ₱ | DC10: =+AB10*CU10 -> 3210.6 | DJ10: Maayos po.
A11: Koro | N11: 01-0003-04 | V11: 1988 | AB11: 2 | AG11: Benches | BM11: Wooden | BU11: Brown | CC11: .90x2.00m. | CS11: ₱ | CU11: 1070 | DA11: ₱ | DC11: =+AB11*CU11 -> 2140 | DJ11: Maayos po.
N12: 01-0005 | V12: 1988 | AB12: 1 | AG12: Numero ng Awit with Stand | BM12: Wooden | BU12: Brown | CS12: ₱ | CU12: 3949.4 | DA12: ₱ | DC12: =+AB12*CU12 -> 3949.4 | DJ12: Luma na po.
N13: 01-0006 | V13: 35547 | AB13: 1 | AG13: Organ | AW13: Yamaha | BE13: EL-15 F | BM13: Wooden | BU13: Brown | CK13: 1902460 | CS13: ₱ | CU13: 73500 | DA13: ₱ | DC13: =+AB13*CU13 -> 73500 | DJ13: Maayos po.
N14: 01-0007 | V14: 35547 | AB14: 1 | AG14: Stool (Organ) | AW14: (Kasama sa halaga ng Organ) | CS14: ₱ | CU14: 0 | DA14: ₱ | DC14: =+AB14*CU14 -> 0 | DJ14: Maayos po.
N15: 01-0008 | V15: 1999 | AB15: 1 | AG15: Digital Hymn Number Control | BM15: Glass | BU15: Black | CS15: ₱ | CU15: 10500 | DA15: ₱ | DC15: =+AB15*CU15 -> 10500 | DJ15: Maayos po.
N16: 01-0009 | V16: 37759 | AB16: 1 | AG16: Wall Fan | AW16: KDK | BE16: W4OY-BW | BM16: Plastic | BU16: Blue | CK16: 322109129 | CS16: ₱ | CU16: 1370 | DA16: ₱ | DC16: =+AB16*CU16 -> 1370 | DJ16: Maayos po.
N17: 01-0010 | V17: 37759 | AB17: 1 | AG17: Wall Fan | AW17: KDK | BE17: W4OY-BW | BM17: Plastic | BU17: Blue | CC17: Std. | CK17: 312408725 | CS17: ₱ | CU17: 1370 | DA17: ₱ | DC17: =+AB17*CU17 -> 1370 | DJ17: Maayos po.
N18: 01-0011 | V18: 39517 | AB18: 1 | AG18: Organ | AW18: Yamaha | BE18: EL-500 | BM18: Wooden | BU18: Black | CC18: (Hiningi sa lokal ng Batangas City) | CK18: 601665 | CS18: ₱ | CU18: 320500 | DA18: ₱ | DC18: =+AB18*CU18 -> 320500 | DJ18: Maayos po.
N19: 01-0012 | V19: 39517 | AB19: 1 | AG19: Organ Chair | BM19: Wooden / Foam | BU19: Black | CS19: ₱ | CU19: 0 | DA19: ₱ | DC19: =+AB19*CU19 -> 0 | DJ19: Maayos po.
A20: Kapilya | N20: 02-0001-05 | V20: 1988 | AB20: 5 | AG20: Tribunal Chair | BM20: Wooden | BU20: Beige | CS20: ₱ | CU20: 1590 | DA20: ₱ | DC20: =+AB20*CU20 -> 7950 | DJ20: Maayos po.
A21: Koro | N21: 02-0007-08 | V21: 1988 | AB21: 2 | AG21: Microphone with Gooseneck | BM21: Metal | BU21: Black | CS21: ₱ | CU21: 1275 | DA21: ₱ | DC21: =+AB21*CU21 -> 2550 | DJ21: Maayos po.
N22: 02-0009 | V22: 34133 | AB22: 1 | AG22: Bible (MB) | BU22: Maroon | CS22: ₱ | CU22: 150 | DA22: ₱ | DC22: =+AB22*CU22 -> 150 | DJ22: Maayos po.
N23: 02-0010 | V23: 1988 | AB23: 1 | AG23: Aklat ng Referencia | BU23: Green | CS23: ₱ | CU23: 30 | DA23: ₱ | DC23: =+AB23*CU23 -> 30 | DJ23: Maayos po.
N24: 02-0011 | V24: 2001 | AB24: 1 | AG24: Bibliya ng Sambayanang Pilipino | BU24: Maroon | CS24: ₱ | CU24: 250 | DA24: ₱ | DC24: =+AB24*CU24 -> 250 | DJ24: Maayos po.
N25: 02-0012 | V25: 2001 | AB25: 1 | AG25: Bibliya-Dating Salin (Tagalog) | BU25: Black | CS25: ₱ | CU25: 250 | DA25: ₱ | DC25: =+AB25*CU25 -> 250 | DJ25: Maayos po.
N26: 02-0014 | V26: 2001 | AB26: 1 | AG26: Bibliya (NPV) | BU26: Blue | CS26: ₱ | CU26: 285 | DA26: ₱ | DC26: =+AB26*CU26 -> 285 | DJ26: Maayos po.
N27: 02-0015 | V27: 37558 | AB27: 1 | AG27: Carpet | BM27: Wool | BU27: Blue-Gray | CC27: 38.43sq.m. | CS27: ₱ | CU27: 21000 | DA27: ₱ | DC27: =+AB27*CU27 -> 21000 | DJ27: Maayos po.
N28: 02-0020 | V28: 37759 | AB28: 1 | AG28: Rota-aire | AW28: KDK | BE28: BF4OAK | BM28: Plastic | BU28: Brown | CC28: Big | CK28: FA2164642 | CS28: ₱ | CU28: 1930 | DA28: ₱ | DC28: =+AB28*CU28 -> 1930 | DJ28: Maayos po.
N29: 02-0021 | V29: Nov. 2004 | AB29: 1 | AG29: Bibliya | BU29: Blue | CS29: ₱ | CU29: 250 | DA29: ₱ | DC29: =+AB29*CU29 -> 250 | DJ29: Maayos po.
N30: 02-0022 | V30: Nov. 2004 | AB30: 1 | AG30: Bibliya | BU30: Maroon | CS30: ₱ | CU30: 250 | DA30: ₱ | DC30: =+AB30*CU30 -> 250 | DJ30: Maayos po.
N31: 02-0023 | V31: Dec. 2004 | AB31: 1 | AG31: Rota-aire | AW31: KDK | BM31: Plastic | BU31: Brown | CC31: Big | CK31: FA2395853 | CS31: ₱ | CU31: 2100 | DA31: ₱ | DC31: =+AB31*CU31 -> 2100 | DJ31: Maayos po.
N32: 02-0024 | V32: 39292 | AB32: 1 | AG32: Vacuum Cleaner | AW32: Turbo | BE32: VacZB300-258 | BM32: Plastic | BU32: Gray | CS32: ₱ | CU32: 2800 | DA32: ₱ | DC32: =+AB32*CU32 -> 2800 | DJ32: Maayos po.
N33: 02-0025-27 | V33: 39383 | AB33: 3 | AG33: Gooseneck Microphones | AW33: SHBOD | BE33: AK-370 | BM33: Metal | BU33: Black | CS33: ₱ | CU33: 2000 | DA33: ₱ | DC33: =+AB33*CU33 -> 6000 | DJ33: Maayos po.
N34: 02-0028 | V34: 39383 | AB34: 1 | AG34: Microphone Stand (Folding Type with Boom) | BM34: Metal | BU34: Black | CS34: ₱ | CU34: 800 | DA34: ₱ | DC34: =+AB34*CU34 -> 800 | DJ34: Maayos po.
N35: 02-0029-37 | V35: 39733 | AB35: 1 | AG35: Cloth Cover of Tribunal Chairs (9 pcs per set) | BM35: Cloth | BU35: Green | CC35: Assorted | CS35: ₱ | CU35: 2000 | DA35: ₱ | DC35: =+AB35*CU35 -> 2000 | DJ35: Maayos po.
DA36: ₱ | DC36: =SUM(DC10:DI35) -> 465135
DJ37: Page 2 | DP37: - 1
A42: Taunang ulat ukol sa Imbentaryo (P-7)
A43: Lokal: | G43: Balayan | AF43: Distrito: | AM43: Batangas | BU43: Dcode: | CA43: 1009 | CJ43: Lcode: | CP43: 003 | DG43: Year: | DM43: 2024
A45: II-A. Mga kagamitan ng lokal ayon sa ulat ng nakaraang taon: (Tiyakin na ang lahat ng dati ng kagamitan na nasa ulat ng nakaraang taon ay nakatala sa bahaging ito ng ayon sa bawat dakong kinaroroonan ng mga ito. Huwag itala
A46: sa bahaging ito ang mga kagamitang hindi naisama sa ulat ng nakaraang taon at ang mga nadagdag sa taong ito.)
V48: Date | AW48: D E S C R I P T I O N
A49: Kaukulan | N49: IIN | V49: Received | AB49: Qty | AG49: Items | AW49: Brand | BE49: Model | BM49: Make | BU49: Color | CC49: Size | CK49: Serial# | CS49: Unit Price | DA49: Amount | DJ49: Remarks
...

Sheet PAGE 3
A2: Taunang ulat sa Imbentaryo (P-7)
A3: Lokal: | G3: Balayan | AB3: Distrito: | AI3: Batangas | BQ3: Dcode: | BX3: 1009 | CG3: Lcode: | CN3: 3 | DD3: Year: | DJ3: 2024
A5: II-B. Nadagdag na mga kagamitan sa taong ito: (Tiyakin na ang lahat ng kagamitan na nakatala dito ay may pinagtibay na P-10 o P-10-2 at naiulat na sa P-7-E.)
X7: Date | BF7: D E S C R I P T I O N | CV7: Unit | DM7: P10# or
A8: Dako/Kaukulan | P8: IIN | X8: Received | AD8: Qty | AI8: Items | BF8: Brand | BM8: Model | BT8: Make | CA8: Color | CH8: Size | CO8: Serial# | CV8: Price | DC8: Amount | DM8: P10-2#
A9: Kalihiman | P9: 27-0114 | X9: 44941 | AD9: 1 | AI9: Printer /unit | BF9: Brother | BM9: DCP-T720DW | BT9: Metal & Plastic | CA9: Black | CO9: E80726K2H29306 | CV9: 15000 | DC9: 15000 | DM9: 42180
A10: Koro | P10: 01-0013 | X10: 45099 | AD10: 1 | AI10: Speaker (portable) /set | BF10: Kevler | BM10: EON-10A | BT10: Metal&Plastic | CA10: Black&yellow | CH10: 10" | CV10: 8000 | DC10: 8000 | DM10: 49067
A11: Kalihiman | P11: 27-0115 | X11: 45277 | AD11: 1 | AI11: Toshiba Photocopier / unit | BF11: Toshiba | BM11: E-Studio2523A | BT11: Metal&Plastic | CA11: Black & White | CO11: CPHM57624 | CV11: 50000 | DC11: 50000 | DM11: 130
BT21: KABUUANG HALAGA …………. | DC21: ₱ | DE21: =SUM(DC9:DL11) -> 73000 | DU21: =+DE21 -> 73000
DN22: Page 3

Sheet PAGE 4
A2: Taunang ulat ukol sa Imbentaryo (P-7)
A3: Lokal: | G3: Balayan | AG3: Distrito: | AN3: Batangas | BU3: Dcode: | CA3: 1009 | CH3: Lcode: | CN3: 3 | DH3: Year: | DM3: 2024
A5: II-C. Nabawas na mga kagamitan sa taong ito: (Tiyakin na ang lahat ng kagamitan na nakatala dito ay may sulat-kahilingang pinagtibay ng Central at iniulat sa P-7-E.)
CQ7: Dahilan
A8: Dakong Pinagmulan o | AD8: Date | CQ8: (Ipinagbili, Ipinamigay, | DK8: Approved
A9: Gumamit | Q9: IIN | AD9: Received | AJ9: Qty | AO9: Items | BY9: Unit Price | CE9: Amount | CQ9: Itinapon, nawala, iba pa) | DK9: Number
AO10: Wala po.
A33: KABUUANG HALAGA NG NABAWAS SA TAONG ITO …………… | CE33: Wala po.
A34: R E S U M E N
A35: II-A | Q35: Kabuuang Halaga ng mga Kagamitan ayon sa ulat ng nakaraang taon ……………………………………….. | CM35: ₱ | CR35: =+'PAGE 2'!DU396 -> 1606934.9
A36: II-B | Q36: Idagdag: Kabuuang Halaga ng NADAGDAG sa taong ito ……………………………………………………. | CM36: ₱ | CR36: =+'PAGE 3'!DU21 -> 73000
A37: II-C | Q37: Ibawas: Kabuuang Halaga ng NABAWAS sa taong ito ………………………………………………………… | CM37: ₱ | CR37: Wala po
A38: KABUUANG HALAGA NG MGA KAGAMITAN SA TAONG ITO …………. | CM38: ₱ | CR38: =SUM(CR35:CR37) -> 1679934.9 | DU38: =+CR38 -> 1679934.9
DN39: Page 4

Sheet PAGE 5
A2: Taunang Ulat ukol sa Imbentaryo (P-7)
B3: Lokal: | H3: Balayan | AA3: Distrito: | AH3: Batangas | BA3: Year: | BG3: 2024
BA4: Lcode: | BG4: 003 | BN4: 1009
A5: III. UKOL SA LUPA: (Ang itala lamang dito ay ang pag-aaral ng Iglesia)
AE6: Area | AL6: Date | BO6: Pansin
B7: Lupa | F7: Complete Address | AE7: (Sq.mtrs.) | AL7: Acquired | AS7: Halaga | BC7: Gusali na nasa lupa | BO7: (Titulado/Free Patent)
B8: 1 | F8: Calzada,Balayan, Batangas | AE8: 2000 | AL8: 25592 | AS8: 16000 | BC8: Kapilya,Pastoral House, Bahay-Bantay Kapilya,Opisina, Pump House, Guard House
B9: 2
B10: 3
B11: Nadagdag: Lupang nabili sa taong ito:
B13: Nabawas: Lupang ibinawas sa taong ito: (Maglakip ng paliwanag.)
B15: KABUUANG HALAGA NG LUPA SA TAONG ITO ……… | BO15: ₱ | BQ15: 16000 | CA15: =+BQ15 -> 16000
B16: Kung wala pang sariling lupa ang lokal, ano ang lupang kinatatayuan ng kapilya? | AU16: ( | AW16: ) | AX16: hiram | BC16: ( | BE16: ) | BF16: lease
B17: Kanino? | AB17: Ilang taon ang kontrata? | BE17: Halaga:
A18: IV. UKOL SA PANANIM: (Sa "Uri" ay ilagay kung ang pananim ay (a) Nagbubunga (b) Hindi Nagbubunga)
S19: Nakaraan | AE19: Nadagdag | AQ19: Nabawas | BC19: Kabuuan Ngayon
B20: Pangalan ng Pananim | N20: Uri | S20: Blg | Y20: Halaga | AE20: Blg | AK20: Halaga | AQ20: Blg | AW20: Halaga | BC20: Blg | BK20: Halaga
B21: Mangga(Indian) | N21: a | S21: 1 | Y21: 150 | AE21: wala po | AQ21: wala po. | BC21: 1 | BK21: ₱ | BM21: 150
B22: Mangga( Piko) | N22: a | S22: 1 | Y22: 100 | AE22: wala po | AQ22: wala po. | BC22: 1 | BK22: ₱ | BM22: 100
B31: KABUUANG HALAGA NG MGA PANANIM SA TAONG ITO ……… | BK31: ₱ | BM31: =+BM21+BM22 -> 250 | CA31: =+BM31 -> 250
A32: V. UKOL SA SASAKYAN:
B33: A. MGA SASAKYAN NG DISTRITO AYON SA ULAT NG NAKARAANG TAON:
B34: DESCRIPTION | S34: VEHICLE 1 | AE34: VEHICLE 2 | AQ34: VEHICLE 3 | BC34: VEHICLE 4 | BO34: VEHICLE 5
B35: MAKE & TYPE
B36: PLATE NUMBER
B37: YEAR MODEL
B38: DATE PURCHASED
B39: ASSIGNED USER (NAME)
B40: DESIGNATION
B41: HALAGA
B43: KABUUANG HALAGA NG MGA SASAKYAN AYON SA ULAT NG NAKARAANG TAON | BC43: P | BF43: Wala po | CA43: 0
B45: B. NADAGDAG SA TAONG ITO: | AN45: C. NABAWAS SA TAONG ITO:
B46: DESCRIPTION | AN46: DESCRIPTION
B47: MAKE & TYPE | AN47: MAKE & TYPE
B48: PLATE NUMBER | AN48: PLATE NUMBER
B49: YEAR MODEL | AN49: YEAR MODEL
B50: DATE PURCHASED | AN50: DATE PURCHASED
B51: ASSIGNED USER (NAME) | AN51: ASSIGNED USER (NAME)
B52: DESIGNATION | AN52: DESIGNATION
B53: SAAN GALING | AN53: SAAN GALING
...

Sheet PAGE 6
A2: Taunang Ulat ukol sa Imbentaryo (P-7)
A3: Lokal: | G3: Balayan | AA3: Distrito: | AH3: Batangas | BA3: Dcode: | BG3: 1009 | BN3: Lcode: | BT3: 3
A7: R E S U M E N
A9: 1. | D9: MGA GUSALI:
F10: A. KAPILYA | AP10: ₱ | AS10: =+'PAGE 1'!CA21 -> 1897535.5
F11: B. PASTORAL & RES. HOUSES | AP11: ₱ | AS11: =+'PAGE 1'!CA32 -> 288611.12
F12: C. OPISINA | AP12: ₱ | AS12: =+'PAGE 1'!CA39 -> 125874.82
F13: D. IBA PANG MGA GUSALI | AP13: ₱ | AS13: =+'PAGE 1'!CA46 -> 126272.49
D14: KABUUANG HALAGA NG MGA GUSALI | BI14: ₱ | BL14: =+'PAGE 1'!CA48 -> 2438293.9
A15: 2. | D15: KABUUANG HALAGA NG MGA KAGAMITAN | BI15: ₱ | BL15: =+'PAGE 4'!DU38 -> 1679934.9
A16: 3. | D16: KABUUANG HALAGA NG MGA LUPA | BI16: ₱ | BL16: =+'PAGE 5'!CA15 -> 16000
A17: 4. | D17: KABUUANG HALAGA NG MGA PANANIM | BI17: ₱ | BL17: =+'PAGE 5'!CA31 -> 250
A18: 5. | D18: KABUUANG HALAGA NG MGA SASAKYAN | BI18: ₱ | BL18: =+'PAGE 5'!CA43 -> 0
D19: KABUUANG HALAGA NG MGA ARI-ARIAN SA TAONG ITO | BI19: ₱ | BL19: =SUM(BL14:BZ18) -> 4134478.9
A23: MGA NAGPAPATOTOO
F25: Pinatutunayan namin na ang mga nakatala sa ulat na ito ay pawang totoo at pawang pag-aari ng
A26: Iglesia sa aming lokal. Nagsagawa kami ng kaukulang "ocular inspection/actual inventory" at natiyak namin
A27: na ang lahat ng mga ari-arian ng Iglesia sa aming lokal ay nakatala dito sa Imbentaryo.
A29: Edelberta U. Villadolid | AA29: Daisy A. Sismundo | BA29: Celestino L. Barrion
A30: Auditor ng Lupon | AA30: Auditor ng Lokal | BA30: Katiwala sa P-7
A31: Carmi C. Pesigan | AA31: Evangeline A. Apolinar | BA31: Radison a. Chavez
A32: Ingat-Yaman ng Lupon | AA32: Ingat-Yaman ng Lokal | BA32: Auditor ng Distrito
A33: Elsie A. Guico | AA33: Genaro B. Layug | BA33: Carlos G. Evangelista, III
A34: Pangulo ng Lupon | AA34: PD-Tagasubaybay | BA34: Ingat-Yaman ng Distrito
A35: Dionisio B. Salazar | AA35: Romeo M. Villaflor Jr. | BA35: Pedro F. Castillo
A36: Obispo/Pangulong Diakono | AA36: Destinado/Pastor ng Lokal | BA36: Tagapangasiwa ng Distrito
A37: Nota: Isulat muna ng palimbag (print) ang pangalan bago lagdaan.
A38: DCG/ludy_cab@P7.2019
BT39: Page 6
